<?xml version="1.0" encoding="utf-8"?>
<!-- This URDF was automatically created by SolidWorks to URDF Exporter! Originally created by Stephen Brawner (brawner@gmail.com) 
     Commit Version: 1.6.0-4-g7f85cfe  Build Version: 1.6.7995.38578
     For more information, please see http://wiki.ros.org/sw_urdf_exporter -->
<robot
  name="toy_car">
  <link
    name="Base_link">
    <inertial>
      <origin
        xyz="-0.0426285345046141 -4.22003044919864E-05 0.14198616644932"
        rpy="0 0 0" />
      <mass
        value="118.777773304167" />
      <inertia
        ixx="3.44533078588298"
        ixy="-0.00106373919126701"
        ixz="0.546779270877047"
        iyy="7.37765984418302"
        iyz="-0.000775828384406624"
        izz="8.06320159688355" />
    </inertial>
    <visual>
      <origin
        xyz="0 0 0"
        rpy="0 0 0" />
      <geometry>
        <mesh
          filename="package://toy_car/meshes/Base_link.STL" />
      </geometry>
      <material
        name="">
        <color
          rgba="0.00784313725490196 0.23921568627451 0.823529411764706 1" />
      </material>
    </visual>
    <collision>
      <origin
        xyz="0 0 0"
        rpy="0 0 0" />
      <geometry>
        <mesh
          filename="package://toy_car/meshes/Base_link.STL" />
      </geometry>
    </collision>
  </link>
  <link
    name="Joint1_Link">
    <inertial>
      <origin
        xyz="0 -8.32667268468867E-17 -0.0301616627241313"
        rpy="0 0 0" />
      <mass
        value="0.124130848717505" />
      <inertia
        ixx="0.0004830988736972"
        ixy="1.28902531710661E-05"
        ixz="-9.3173624197973E-20"
        iyy="0.000283667508714675"
        iyz="-2.55803950070799E-19"
        izz="0.000276878735483341" />
    </inertial>
    <visual>
      <origin
        xyz="0 0 0"
        rpy="0 0 0" />
      <geometry>
        <mesh
          filename="package://toy_car/meshes/Joint1_Link.STL" />
      </geometry>
      <material
        name="">
        <color
          rgba="0.694117647058824 0.0980392156862745 0.0980392156862745 1" />
      </material>
    </visual>
    <collision>
      <origin
        xyz="0 0 0"
        rpy="0 0 0" />
      <geometry>
        <mesh
          filename="package://toy_car/meshes/Joint1_Link.STL" />
      </geometry>
    </collision>
  </link>
  <joint
    name="Joint1"
    type="revolute">
    <origin
      xyz="0.3556 0.1651 -0.03175"
      rpy="0 0 3.0773" />
    <parent
      link="Base_link" />
    <child
      link="Joint1_Link" />
    <axis
      xyz="0 0 1" />
    <limit
      lower="-0.61"
      upper="0.61"
      effort="0"
      velocity="0" />
  </joint>
  <link
    name="Pin1_Link">
    <inertial>
      <origin
        xyz="-0.00283811998654371 0.0761470399666677 0.00011566873687055"
        rpy="0 0 0" />
      <mass
        value="0.16540999484257" />
      <inertia
        ixx="0.000334731358482015"
        ixy="1.13572747544458E-05"
        ixz="1.72519066494735E-08"
        iyy="3.0437856934387E-05"
        iyz="-4.62870361847676E-07"
        izz="0.000335153958872749" />
    </inertial>
    <visual>
      <origin
        xyz="0 0 0"
        rpy="0 0 0" />
      <geometry>
        <mesh
          filename="package://toy_car/meshes/Pin1_Link.STL" />
      </geometry>
      <material
        name="">
        <color
          rgba="0.498039215686275 0.498039215686275 0.498039215686275 1" />
      </material>
    </visual>
    <collision>
      <origin
        xyz="0 0 0"
        rpy="0 0 0" />
      <geometry>
        <mesh
          filename="package://toy_car/meshes/Pin1_Link.STL" />
      </geometry>
    </collision>
  </link>
  <joint
    name="Pin1"
    type="fixed">
    <origin
      xyz="0.0049762 -0.07731 -0.10795"
      rpy="0 -0.040733 0.026993" />
    <parent
      link="Joint1_Link" />
    <child
      link="Pin1_Link" />
    <axis
      xyz="0 0 0" />
  </joint>
  <link
    name="Wheel1_Link">
    <inertial>
      <origin
        xyz="-0.00216214695104683 0.0352298141764032 -0.00113862677348732"
        rpy="0 0 0" />
      <mass
        value="1.46371001105716" />
      <inertia
        ixx="0.00585520773581656"
        ixy="-0.0002773491858025"
        ixz="-2.29367543191264E-06"
        iyy="0.0101926207957827"
        iyz="-0.000165331158740007"
        izz="0.00584658665447184" />
    </inertial>
    <visual>
      <origin
        xyz="0 0 0"
        rpy="0 0 0" />
      <geometry>
        <mesh
          filename="package://toy_car/meshes/Wheel1_Link.STL" />
      </geometry>
      <material
        name="">
        <color
          rgba="0.298039215686275 0.298039215686275 0.298039215686275 1" />
      </material>
    </visual>
    <collision>
      <origin
        xyz="0 0 0"
        rpy="0 0 0" />
      <geometry>
        <mesh
          filename="package://toy_car/meshes/Wheel1_Link.STL" />
      </geometry>
    </collision>
  </link>
  <joint
    name="Wheel1"
    type="continuous">
    <origin
      xyz="-0.0014664 0.039343 5.9762E-05"
      rpy="0.041225 0.0011128 -0.026972" />
    <parent
      link="Pin1_Link" />
    <child
      link="Wheel1_Link" />
    <axis
      xyz="-0.064184 0.99715 -0.039683" />
    <limit
      effort="0"
      velocity="100" />
  </joint>
  <link
    name="Joint2_Link">
    <inertial>
      <origin
        xyz="-5.55111512312578E-17 5.55111512312578E-17 -0.030161662724131"
        rpy="0 0 0" />
      <mass
        value="0.124130848717504" />
      <inertia
        ixx="0.000483098873697198"
        ixy="1.2890253171066E-05"
        ixz="-2.35475159336695E-19"
        iyy="0.000283667508714673"
        iyz="1.88041314290455E-19"
        izz="0.000276878735483341" />
    </inertial>
    <visual>
      <origin
        xyz="0 0 0"
        rpy="0 0 0" />
      <geometry>
        <mesh
          filename="package://toy_car/meshes/Joint2_Link.STL" />
      </geometry>
      <material
        name="">
        <color
          rgba="0.694117647058824 0.0980392156862745 0.0980392156862745 1" />
      </material>
    </visual>
    <collision>
      <origin
        xyz="0 0 0"
        rpy="0 0 0" />
      <geometry>
        <mesh
          filename="package://toy_car/meshes/Joint2_Link.STL" />
      </geometry>
    </collision>
  </link>
  <joint
    name="Joint2"
    type="revolute">
    <origin
      xyz="0.3556 -0.1651 -0.03175"
      rpy="0 0 3.0773" />
    <parent
      link="Base_link" />
    <child
      link="Joint2_Link" />
    <axis
      xyz="0 0 1" />
    <limit
      lower="-0.78"
      upper="0.78"
      effort="0"
      velocity="0" />
  </joint>
  <link
    name="Pin2_Link">
    <inertial>
      <origin
        xyz="-0.00489465473131923 0.07604263511387 0"
        rpy="0 0 0" />
      <mass
        value="0.16540999484257" />
      <inertia
        ixx="0.000333895636619403"
        ixy="1.95600326160731E-05"
        ixz="0"
        iyy="3.12728756885116E-05"
        iyz="5.71747239396653E-21"
        izz="0.000335154661981237" />
    </inertial>
    <visual>
      <origin
        xyz="0 0 0"
        rpy="0 0 0" />
      <geometry>
        <mesh
          filename="package://toy_car/meshes/Pin2_Link.STL" />
      </geometry>
      <material
        name="">
        <color
          rgba="0.498039215686275 0.498039215686275 0.498039215686275 1" />
      </material>
    </visual>
    <collision>
      <origin
        xyz="0 0 0"
        rpy="0 0 0" />
      <geometry>
        <mesh
          filename="package://toy_car/meshes/Pin2_Link.STL" />
      </geometry>
    </collision>
  </link>
  <joint
    name="Pin2"
    type="fixed">
    <origin
      xyz="0.0048131 -0.074775 -0.10795"
      rpy="0 0 0" />
    <parent
      link="Joint2_Link" />
    <child
      link="Pin2_Link" />
    <axis
      xyz="0 0 0" />
  </joint>
  <link
    name="Wheel2_Link">
    <inertial>
      <origin
        xyz="0.00210743001370378 -0.0352507507948613 -0.000232860989485217"
        rpy="0 0 0" />
      <mass
        value="1.46371118981023" />
      <inertia
        ixx="0.00586861101108003"
        ixy="-0.000274527148540642"
        ixz="-4.17444925581941E-06"
        iyy="0.0101991535376833"
        iyz="7.45704072127398E-06"
        izz="0.00582664727653024" />
    </inertial>
    <visual>
      <origin
        xyz="0 0 0"
        rpy="0 0 0" />
      <geometry>
        <mesh
          filename="package://toy_car/meshes/Wheel2_Link.STL" />
      </geometry>
      <material
        name="">
        <color
          rgba="0.298039215686275 0.298039215686275 0.298039215686275 1" />
      </material>
    </visual>
    <collision>
      <origin
        xyz="0 0 0"
        rpy="0 0 0" />
      <geometry>
        <mesh
          filename="package://toy_car/meshes/Wheel2_Link.STL" />
      </geometry>
    </collision>
  </link>
  <joint
    name="Wheel2"
    type="continuous">
    <origin
      xyz="-0.0072604 0.1128 0"
      rpy="0 0 0" />
    <parent
      link="Pin2_Link" />
    <child
      link="Wheel2_Link" />
    <axis
      xyz="0.064234 -0.99793 0" />
    <limit
      effort="0"
      velocity="100" />
  </joint>
  <link
    name="Joint3_Link">
    <inertial>
      <origin
        xyz="0 0 -0.0301616627241311"
        rpy="0 0 0" />
      <mass
        value="0.124130848717505" />
      <inertia
        ixx="0.0004830988736972"
        ixy="1.28902531710662E-05"
        ixz="-5.67512074660381E-20"
        iyy="0.000283667508714674"
        iyz="1.64324391767334E-19"
        izz="0.000276878735483342" />
    </inertial>
    <visual>
      <origin
        xyz="0 0 0"
        rpy="0 0 0" />
      <geometry>
        <mesh
          filename="package://toy_car/meshes/Joint3_Link.STL" />
      </geometry>
      <material
        name="">
        <color
          rgba="0.694117647058824 0.0980392156862745 0.0980392156862745 1" />
      </material>
    </visual>
    <collision>
      <origin
        xyz="0 0 0"
        rpy="0 0 0" />
      <geometry>
        <mesh
          filename="package://toy_car/meshes/Joint3_Link.STL" />
      </geometry>
    </collision>
  </link>
  <joint
    name="Joint3"
    type="fixed">
    <origin
      xyz="-0.3556 0.1651 -0.03175"
      rpy="0 0 3.0773" />
    <parent
      link="Base_link" />
    <child
      link="Joint3_Link" />
    <axis
      xyz="0 0 0" />
  </joint>
  <link
    name="Pin3_Link">
    <inertial>
      <origin
        xyz="-0.00489465473131928 0.07604263511387 0"
        rpy="0 0 0" />
      <mass
        value="0.16540999484257" />
      <inertia
        ixx="0.000333895636619403"
        ixy="1.95600326160732E-05"
        ixz="2.5410988417629E-21"
        iyy="3.12728756885116E-05"
        iyz="9.52912065661088E-21"
        izz="0.000335154661981237" />
    </inertial>
    <visual>
      <origin
        xyz="0 0 0"
        rpy="0 0 0" />
      <geometry>
        <mesh
          filename="package://toy_car/meshes/Pin3_Link.STL" />
      </geometry>
      <material
        name="">
        <color
          rgba="0.498039215686275 0.498039215686275 0.498039215686275 1" />
      </material>
    </visual>
    <collision>
      <origin
        xyz="0 0 0"
        rpy="0 0 0" />
      <geometry>
        <mesh
          filename="package://toy_car/meshes/Pin3_Link.STL" />
      </geometry>
    </collision>
  </link>
  <joint
    name="Pin3"
    type="fixed">
    <origin
      xyz="0.00497623231017452 -0.0773100123657679 -0.10795"
      rpy="0 0 0" />
    <parent
      link="Joint3_Link" />
    <child
      link="Pin3_Link" />
    <axis
      xyz="0 0 0" />
  </joint>
  <link
    name="Wheel3_Link">
    <inertial>
      <origin
        xyz="-0.00254592752160032 0.035222527853133 -5.3127516316559E-05"
        rpy="0 0 0" />
      <mass
        value="1.46371020341956" />
      <inertia
        ixx="0.00584723946937808"
        ixy="-0.000290444959761925"
        ixz="6.73362301462099E-06"
        iyy="0.0101971978158898"
        iyz="-1.32810154552081E-06"
        izz="0.00584998487593019" />
    </inertial>
    <visual>
      <origin
        xyz="0 0 0"
        rpy="0 0 0" />
      <geometry>
        <mesh
          filename="package://toy_car/meshes/Wheel3_Link.STL" />
      </geometry>
      <material
        name="">
        <color
          rgba="0.298039215686275 0.298039215686275 0.298039215686275 1" />
      </material>
    </visual>
    <collision>
      <origin
        xyz="0 0 0"
        rpy="0 0 0" />
      <geometry>
        <mesh
          filename="package://toy_car/meshes/Wheel3_Link.STL" />
      </geometry>
    </collision>
  </link>
  <joint
    name="Wheel3"
    type="continuous">
    <origin
      xyz="-0.00252890494451513 0.0392886948088329 0"
      rpy="0 0 0" />
    <parent
      link="Pin3_Link" />
    <child
      link="Wheel3_Link" />
    <axis
      xyz="-0.0642343140593084 0.997934844014042 0" />
    <limit
      effort="0"
      velocity="100" />
  </joint>
  <link
    name="Joint4_Link">
    <inertial>
      <origin
        xyz="5.55111512312578E-17 5.55111512312578E-17 -0.0301616627241313"
        rpy="0 0 0" />
      <mass
        value="0.124130848717505" />
      <inertia
        ixx="0.000483098873697201"
        ixy="1.28902531710661E-05"
        ixz="-3.64224167319349E-20"
        iyy="0.000283667508714675"
        iyz="4.61632956253594E-19"
        izz="0.000276878735483343" />
    </inertial>
    <visual>
      <origin
        xyz="0 0 0"
        rpy="0 0 0" />
      <geometry>
        <mesh
          filename="package://toy_car/meshes/Joint4_Link.STL" />
      </geometry>
      <material
        name="">
        <color
          rgba="0.694117647058824 0.0980392156862745 0.0980392156862745 1" />
      </material>
    </visual>
    <collision>
      <origin
        xyz="0 0 0"
        rpy="0 0 0" />
      <geometry>
        <mesh
          filename="package://toy_car/meshes/Joint4_Link.STL" />
      </geometry>
    </collision>
  </link>
  <joint
    name="Joint4"
    type="fixed">
    <origin
      xyz="-0.3556 -0.1651 -0.03175"
      rpy="0 0 3.07731408501194" />
    <parent
      link="Base_link" />
    <child
      link="Joint4_Link" />
    <axis
      xyz="0 0 0" />
  </joint>
  <link
    name="Pin4_Link">
    <inertial>
      <origin
        xyz="-0.00489081641915112 0.0759827381930964 -0.00302380743988964"
        rpy="0 0 0" />
      <mass
        value="0.16540999484257" />
      <inertia
        ixx="0.000333897610461414"
        ixy="1.95292990658863E-05"
        ixz="-7.77187572013851E-07"
        iyy="3.17514076273443E-05"
        iyz="1.20742294844724E-05"
        izz="0.000334674156200394" />
    </inertial>
    <visual>
      <origin
        xyz="0 0 0"
        rpy="0 0 0" />
      <geometry>
        <mesh
          filename="package://toy_car/meshes/Pin4_Link.STL" />
      </geometry>
      <material
        name="">
        <color
          rgba="0.498039215686275 0.498039215686275 0.498039215686275 1" />
      </material>
    </visual>
    <collision>
      <origin
        xyz="0 0 0"
        rpy="0 0 0" />
      <geometry>
        <mesh
          filename="package://toy_car/meshes/Pin4_Link.STL" />
      </geometry>
    </collision>
  </link>
  <joint
    name="Pin4"
    type="fixed">
    <origin
      xyz="0.00481307715246387 -0.0747752578619723 -0.10795"
      rpy="0.0423235974745796 -0.0396052261810362 0" />
    <parent
      link="Joint4_Link" />
    <child
      link="Pin4_Link" />
    <axis
      xyz="0 0 0" />
  </joint>
  <link
    name="Wheel4_Link">
    <inertial>
      <origin
        xyz="0.00254926636754543 -0.0352223121973515 -3.08297953219294E-05"
        rpy="0 0 0" />
      <mass
        value="1.46371027395517" />
      <inertia
        ixx="0.00584844026652835"
        ixy="-0.000290478379695307"
        ixz="-8.34565471979886E-06"
        iyy="0.0101971889923073"
        iyz="4.84746873149512E-07"
        izz="0.00584879384195457" />
    </inertial>
    <visual>
      <origin
        xyz="0 0 0"
        rpy="0 0 0" />
      <geometry>
        <mesh
          filename="package://toy_car/meshes/Wheel4_Link.STL" />
      </geometry>
      <material
        name="">
        <color
          rgba="0.298039215686275 0.298039215686275 0.298039215686275 1" />
      </material>
    </visual>
    <collision>
      <origin
        xyz="0 0 0"
        rpy="0 0 0" />
      <geometry>
        <mesh
          filename="package://toy_car/meshes/Wheel4_Link.STL" />
      </geometry>
    </collision>
  </link>
  <joint
    name="Wheel4"
    type="continuous">
    <origin
      xyz="-0.00725471102174091 0.11270772831976 -0.00448531436916969"
      rpy="-0.042356773330912 0.0395697407834747 -0.00167661040974054" />
    <parent
      link="Pin4_Link" />
    <child
      link="Wheel4_Link" />
    <axis
      xyz="0.0642343140593085 -0.997934844014042 0" />
    <limit
      effort="0"
      velocity="100" />
  </joint>
  <link
    name="lidar_Link">
    <inertial>
      <origin
        xyz="2.1446069833897E-07 0.0143700000385549 -3.60722045116002E-08"
        rpy="0 0 0" />
      <mass
        value="0.0107844655207284" />
      <inertia
        ixx="1.06577800938719E-06"
        ixy="9.48672718150391E-13"
        ixz="-1.6180579231452E-12"
        iyy="8.72302781974236E-07"
        iyz="-3.36880671097441E-12"
        izz="1.01017987036267E-06" />
    </inertial>
    <visual>
      <origin
        xyz="0 0 0"
        rpy="0 0 0" />
      <geometry>
        <mesh
          filename="package://toy_car/meshes/lidar_Link.STL" />
      </geometry>
      <material
        name="">
        <color
          rgba="0.498039215686275 0.498039215686275 0.498039215686275 1" />
      </material>
    </visual>
    <collision>
      <origin
        xyz="0 0 0"
        rpy="0 0 0" />
      <geometry>
        <mesh
          filename="package://toy_car/meshes/lidar_Link.STL" />
      </geometry>
    </collision>
  </link>
  <joint
    name="lidar"
    type="fixed">
    <origin
      xyz="-0.1227 0 0.37497"
      rpy="1.5708 0 -0.065659" />
    <parent
      link="Base_link" />
    <child
      link="lidar_Link" />
    <axis
      xyz="0 0 1" />
  </joint>
</robot>